{
 "cells": [
  {
   "cell_type": "code",
   "execution_count": 8,
   "source": [
    "!pip install tensorflow\r\n",
    "!pip install opencv-python\r\n",
    "!pip install matplotlib\r\n",
    "!pip install numpy\r\n"
   ],
   "outputs": [
    {
     "output_type": "stream",
     "name": "stdout",
     "text": [
      "Collecting tensorflow\n",
      "  Downloading tensorflow-2.6.0-cp39-cp39-win_amd64.whl (423.3 MB)\n"
     ]
    },
    {
     "output_type": "stream",
     "name": "stderr",
     "text": [
      "ERROR: Exception:\n",
      "Traceback (most recent call last):\n",
      "  File \"c:\\users\\mashh\\appdata\\local\\programs\\python\\python39\\lib\\site-packages\\pip\\_vendor\\urllib3\\response.py\", line 438, in _error_catcher\n",
      "    yield\n",
      "  File \"c:\\users\\mashh\\appdata\\local\\programs\\python\\python39\\lib\\site-packages\\pip\\_vendor\\urllib3\\response.py\", line 519, in read\n",
      "    data = self._fp.read(amt) if not fp_closed else b\"\"\n",
      "  File \"c:\\users\\mashh\\appdata\\local\\programs\\python\\python39\\lib\\site-packages\\pip\\_vendor\\cachecontrol\\filewrapper.py\", line 62, in read\n",
      "    data = self.__fp.read(amt)\n",
      "  File \"c:\\users\\mashh\\appdata\\local\\programs\\python\\python39\\lib\\http\\client.py\", line 458, in read\n",
      "    n = self.readinto(b)\n",
      "  File \"c:\\users\\mashh\\appdata\\local\\programs\\python\\python39\\lib\\http\\client.py\", line 502, in readinto\n",
      "    n = self.fp.readinto(b)\n",
      "  File \"c:\\users\\mashh\\appdata\\local\\programs\\python\\python39\\lib\\socket.py\", line 704, in readinto\n",
      "    return self._sock.recv_into(b)\n",
      "  File \"c:\\users\\mashh\\appdata\\local\\programs\\python\\python39\\lib\\ssl.py\", line 1241, in recv_into\n",
      "    return self.read(nbytes, buffer)\n",
      "  File \"c:\\users\\mashh\\appdata\\local\\programs\\python\\python39\\lib\\ssl.py\", line 1099, in read\n",
      "    return self._sslobj.read(len, buffer)\n",
      "socket.timeout: The read operation timed out\n",
      "\n",
      "During handling of the above exception, another exception occurred:\n",
      "\n",
      "Traceback (most recent call last):\n",
      "  File \"c:\\users\\mashh\\appdata\\local\\programs\\python\\python39\\lib\\site-packages\\pip\\_internal\\cli\\base_command.py\", line 180, in _main\n",
      "    status = self.run(options, args)\n",
      "  File \"c:\\users\\mashh\\appdata\\local\\programs\\python\\python39\\lib\\site-packages\\pip\\_internal\\cli\\req_command.py\", line 205, in wrapper\n",
      "    return func(self, options, args)\n",
      "  File \"c:\\users\\mashh\\appdata\\local\\programs\\python\\python39\\lib\\site-packages\\pip\\_internal\\commands\\install.py\", line 318, in run\n",
      "    requirement_set = resolver.resolve(\n",
      "  File \"c:\\users\\mashh\\appdata\\local\\programs\\python\\python39\\lib\\site-packages\\pip\\_internal\\resolution\\resolvelib\\resolver.py\", line 127, in resolve\n",
      "    result = self._result = resolver.resolve(\n",
      "  File \"c:\\users\\mashh\\appdata\\local\\programs\\python\\python39\\lib\\site-packages\\pip\\_vendor\\resolvelib\\resolvers.py\", line 473, in resolve\n",
      "    state = resolution.resolve(requirements, max_rounds=max_rounds)\n",
      "  File \"c:\\users\\mashh\\appdata\\local\\programs\\python\\python39\\lib\\site-packages\\pip\\_vendor\\resolvelib\\resolvers.py\", line 341, in resolve\n",
      "    name, crit = self._merge_into_criterion(r, parent=None)\n",
      "  File \"c:\\users\\mashh\\appdata\\local\\programs\\python\\python39\\lib\\site-packages\\pip\\_vendor\\resolvelib\\resolvers.py\", line 172, in _merge_into_criterion\n",
      "    if not criterion.candidates:\n",
      "  File \"c:\\users\\mashh\\appdata\\local\\programs\\python\\python39\\lib\\site-packages\\pip\\_vendor\\resolvelib\\structs.py\", line 139, in __bool__\n",
      "    return bool(self._sequence)\n",
      "  File \"c:\\users\\mashh\\appdata\\local\\programs\\python\\python39\\lib\\site-packages\\pip\\_internal\\resolution\\resolvelib\\found_candidates.py\", line 143, in __bool__\n",
      "    return any(self)\n",
      "  File \"c:\\users\\mashh\\appdata\\local\\programs\\python\\python39\\lib\\site-packages\\pip\\_internal\\resolution\\resolvelib\\found_candidates.py\", line 129, in <genexpr>\n",
      "    return (c for c in iterator if id(c) not in self._incompatible_ids)\n",
      "  File \"c:\\users\\mashh\\appdata\\local\\programs\\python\\python39\\lib\\site-packages\\pip\\_internal\\resolution\\resolvelib\\found_candidates.py\", line 33, in _iter_built\n",
      "    candidate = func()\n",
      "  File \"c:\\users\\mashh\\appdata\\local\\programs\\python\\python39\\lib\\site-packages\\pip\\_internal\\resolution\\resolvelib\\factory.py\", line 200, in _make_candidate_from_link\n",
      "    self._link_candidate_cache[link] = LinkCandidate(\n",
      "  File \"c:\\users\\mashh\\appdata\\local\\programs\\python\\python39\\lib\\site-packages\\pip\\_internal\\resolution\\resolvelib\\candidates.py\", line 306, in __init__\n",
      "    super().__init__(\n",
      "  File \"c:\\users\\mashh\\appdata\\local\\programs\\python\\python39\\lib\\site-packages\\pip\\_internal\\resolution\\resolvelib\\candidates.py\", line 151, in __init__\n",
      "    self.dist = self._prepare()\n",
      "  File \"c:\\users\\mashh\\appdata\\local\\programs\\python\\python39\\lib\\site-packages\\pip\\_internal\\resolution\\resolvelib\\candidates.py\", line 234, in _prepare\n",
      "    dist = self._prepare_distribution()\n",
      "  File \"c:\\users\\mashh\\appdata\\local\\programs\\python\\python39\\lib\\site-packages\\pip\\_internal\\resolution\\resolvelib\\candidates.py\", line 317, in _prepare_distribution\n",
      "    return self._factory.preparer.prepare_linked_requirement(\n",
      "  File \"c:\\users\\mashh\\appdata\\local\\programs\\python\\python39\\lib\\site-packages\\pip\\_internal\\operations\\prepare.py\", line 508, in prepare_linked_requirement\n",
      "    return self._prepare_linked_requirement(req, parallel_builds)\n",
      "  File \"c:\\users\\mashh\\appdata\\local\\programs\\python\\python39\\lib\\site-packages\\pip\\_internal\\operations\\prepare.py\", line 550, in _prepare_linked_requirement\n",
      "    local_file = unpack_url(\n",
      "  File \"c:\\users\\mashh\\appdata\\local\\programs\\python\\python39\\lib\\site-packages\\pip\\_internal\\operations\\prepare.py\", line 239, in unpack_url\n",
      "    file = get_http_url(\n",
      "  File \"c:\\users\\mashh\\appdata\\local\\programs\\python\\python39\\lib\\site-packages\\pip\\_internal\\operations\\prepare.py\", line 102, in get_http_url\n",
      "    from_path, content_type = download(link, temp_dir.path)\n",
      "  File \"c:\\users\\mashh\\appdata\\local\\programs\\python\\python39\\lib\\site-packages\\pip\\_internal\\network\\download.py\", line 157, in __call__\n",
      "    for chunk in chunks:\n",
      "  File \"c:\\users\\mashh\\appdata\\local\\programs\\python\\python39\\lib\\site-packages\\pip\\_internal\\cli\\progress_bars.py\", line 152, in iter\n",
      "    for x in it:\n",
      "  File \"c:\\users\\mashh\\appdata\\local\\programs\\python\\python39\\lib\\site-packages\\pip\\_internal\\network\\utils.py\", line 62, in response_chunks\n",
      "    for chunk in response.raw.stream(\n",
      "  File \"c:\\users\\mashh\\appdata\\local\\programs\\python\\python39\\lib\\site-packages\\pip\\_vendor\\urllib3\\response.py\", line 576, in stream\n",
      "    data = self.read(amt=amt, decode_content=decode_content)\n",
      "  File \"c:\\users\\mashh\\appdata\\local\\programs\\python\\python39\\lib\\site-packages\\pip\\_vendor\\urllib3\\response.py\", line 541, in read\n",
      "    raise IncompleteRead(self._fp_bytes_read, self.length_remaining)\n",
      "  File \"c:\\users\\mashh\\appdata\\local\\programs\\python\\python39\\lib\\contextlib.py\", line 135, in __exit__\n",
      "    self.gen.throw(type, value, traceback)\n",
      "  File \"c:\\users\\mashh\\appdata\\local\\programs\\python\\python39\\lib\\site-packages\\pip\\_vendor\\urllib3\\response.py\", line 443, in _error_catcher\n",
      "    raise ReadTimeoutError(self._pool, None, \"Read timed out.\")\n",
      "pip._vendor.urllib3.exceptions.ReadTimeoutError: HTTPSConnectionPool(host='files.pythonhosted.org', port=443): Read timed out.\n",
      "WARNING: You are using pip version 21.1.3; however, version 21.2.4 is available.\n",
      "You should consider upgrading via the 'c:\\users\\mashh\\appdata\\local\\programs\\python\\python39\\python.exe -m pip install --upgrade pip' command.\n"
     ]
    }
   ],
   "metadata": {}
  },
  {
   "cell_type": "code",
   "execution_count": null,
   "source": [
    "import tensorflow as tf\r\n",
    "import cv2\r\n",
    "import os\r\n",
    "import matplotlib as plt\r\n",
    "import numpy as np\r\n",
    "print(\"done!\")"
   ],
   "outputs": [],
   "metadata": {}
  },
  {
   "cell_type": "code",
   "execution_count": null,
   "source": [
    "!pip install tensorflow\r\n",
    "!pip install opencv-python\r\n",
    "!pip install matplotlib\r\n",
    "!pip install numpy\r\n"
   ],
   "outputs": [],
   "metadata": {}
  },
  {
   "cell_type": "markdown",
   "source": [
    "# Importing the files\r\n"
   ],
   "metadata": {}
  },
  {
   "cell_type": "code",
   "execution_count": null,
   "source": [],
   "outputs": [],
   "metadata": {}
  },
  {
   "cell_type": "code",
   "execution_count": null,
   "source": [],
   "outputs": [],
   "metadata": {}
  }
 ],
 "metadata": {
  "kernelspec": {
   "name": "python3",
   "display_name": "Python 3.9.2 64-bit"
  },
  "language_info": {
   "codemirror_mode": {
    "name": "ipython",
    "version": 3
   },
   "file_extension": ".py",
   "mimetype": "text/x-python",
   "name": "python",
   "nbconvert_exporter": "python",
   "pygments_lexer": "ipython3",
   "version": "3.9.2"
  },
  "interpreter": {
   "hash": "d3ef358e1fac5dce7663f42a1be880e41d27997f5e429f52a29c90ea33e11bf3"
  }
 },
 "nbformat": 4,
 "nbformat_minor": 5
}